Workbook
Name _GoBack: Consolidado!$AQ$65
Name Con_R.C.: 'Listas (2)'!$B$26:$B$27
Name Con_R.C.: Listas!$B$26:$B$27
Name Excel_BuiltIn__FilterDatabase_7: #REF!
Name Excel_BuiltIn__FilterDatabase_7: #REF!
Name Excel_BuiltIn__FilterDatabase_7: #REF!
Name Excel_BuiltIn__FilterDatabase_7: #REF!
Name Excel_BuiltIn__FilterDatabase_7: #REF!
Name Excel_BuiltIn__FilterDatabase_8: #REF!
Name Excel_BuiltIn__FilterDatabase_8: #REF!
Name Excel_BuiltIn__FilterDatabase_8: #REF!
Name Excel_BuiltIn__FilterDatabase_8: #REF!
Name Excel_BuiltIn__FilterDatabase_8: #REF!
Name Excel_BuiltIn_Print_Area_10: #REF!
Name Excel_BuiltIn_Print_Area_10: #REF!
Name Excel_BuiltIn_Print_Area_10: #REF!
Name Excel_BuiltIn_Print_Area_10: #REF!
Name Excel_BuiltIn_Print_Area_10: #REF!
Name Modelo: 'Listas (2)'!$B$30:$B$31
Name Modelo: Listas!$B$30:$B$31
Name Nivel: [1]Consolidado!#REF!
Name Nivel: [1]Consolidado!#REF!
Name Nivel: #REF!
Name Nivel: Consolidado!#REF!
Name NivelPrePos: Listas!$B$10:$B$11
Name NivelPrePos: 'Listas (2)'!$B$10:$B$11
Name NivelPrePos: Listas!$B$10:$B$11
Name NivelU: 'Listas (2)'!$B$10:$B$11
Name NivelU: Listas!$B$10:$B$11
Name Por_extensión: [1]Consolidado!#REF!
Name Por_extensión: [1]Consolidado!#REF!
Name Por_extensión: #REF!
Name Por_extensión: Consolidado!#REF!
Name Regionalizacion: Listas!$B$4:$B$7
Name Regionalizacion: 'Listas (2)'!$B$4:$B$7
Name Regionalizacion: Listas!$B$4:$B$7
Name Regionalizacion: Listas!$B$4:$B$7
Name Salas: 'Listas (2)'!$B$14:$B$22
Name Salas: Listas!$B$14:$B$22
Name Si: [1]Consolidado!#REF!
Name Si: [1]Consolidado!#REF!
Name Si: #REF!
Name Si: Consolidado!#REF!
Name SiNo: Listas!$B$26:$B$27
Name SiNo: 'Listas (2)'!$B$26:$B$27
Name SiNo: Listas!$B$26:$B$27
Name SiNo: Listas!$B$26:$B$27
Name w: #REF!
Name w: #REF!
Name w: #REF!

Sheet Menú
E13: Centro de Gestión de Calidad y Acreditación Institucional
E14: Sistema Integrado de Gestión para la Acreditación SiGA
F15: Base de Datos Maestra del CGC-AI
C17: Listado Programas con RC | D17: Resumen Programas con RC | E17: Programas Acreditables | F17: Programas Acreditados | G17: Estado proceso Renovación RC por programa | H17: Resumen proceso Renovación RC | I17: Estado proceso AAC por programa | J17: Resumen proceso AAC
C23: RC: Registro Calificado | E23: AAC:Acreditación Alta Calidad
B26: Actualizada a 4 de junio de 2024

Sheet Consolidado
A1: Asignación de código SNIES para programas académicos
C2: Centro de Gestión de Calidad y Acreditación Institucional
C3: Sistema Interno de Aseguramiento de la Calidad
C4: Información de Programas Académicos de la Universidad del Cauca
A6: N° | B6: Código Proceso | C6: Facultad | D6: Programa | E6: Título otorgado | F6: Acuerdo de Creación Consejo Superior | G6: SNIES | H6: No Renovación | I6: Número de Admitidos autorizados por el MEN | J6: Periodicidad del admisión | K6: Convenio | L6: IES en Convenio | M6: Administrador de convenio | N6: Lugar de Desarrollo | O6: Jornada | P6: Regionalizado | Q6: Nivel de formación académico | R6: Nivel académico | S6: Modalidad | T6: Metodología | U6: Créditos Investigación | V6: Créditos Profundización | W6: Total Créditos Académicos | X6: Duración | Y6: Reforma Consejo Académico | Z6: Reforma Consejo Superior | AA6: Reforma MinEducación | AB6: % TIC | AC6: Con R.C. | AD6: Resolución R.C. | AE6: Resolución R.C. | AF6: Inicio R.C. | AG6: Duración (años) | AH6: SiGA RRC (14 meses antes) | AI6: Plazo Radicación RRC ante MinEducación (12 meses antes) | AJ6: Vencimiento R.C. | AK6: Extensión Decreto 1330 de 2019 | AL6: Vencimiento de R.C con Extensión decreto 1174 de 2023 | AM6: Histórico Resoluciones R.C. | AN6: Cantidad Res/Ren R.C. | AO6: Resolución R.C. de Oficio | AP6: Resolución R.C. Negada | AQ6: Número Egresados | AR6: Acreditable | AS6: Acreditado | AT6: En Proceso de Acreditación | AU6: Resolución Acreditación A.C. | AV6: Inicio A.A.C. | AW6: Duración (años) | AX6: Entrega al CGCAI (14 meses antes) | AY6: Plazo Radicación AAC ante MinEducación (1 año antes) | AZ6: Vencimiento A.A.C. | BA6: Mitad Vigencia de Acreditación (Plan de Mejora) | BB6: Histórico Resoluciones AAC | BC6: Cantidad Res. AAC | BD6: Resolución AAC Negada | BE6: Lineamiento Acreditación | BF6: Observaciones Generales | BG6: Coordinador de Programa
A7: 1 | B7: 29672 | C7: Facultad de Artes | D7: Artes Plásticas | E7: Maestro en Artes Plásticas | F7: Ac. 006 de 17-Feb-1996 (CS) Reforma 04 de 03-Feb-2010 | G7: 224 | I7: 30 (2021) | J7: Semestral | N7: Popayán | O7: Diurna | P7: No | Q7: Profesional Universitario | R7: Pregrado | S7: Presencial | T7: N/A | U7: N/A | V7: N/A | W7: 158 | X7: 10 Semestres | AB7: 0.35 | AC7: =IF(AJ7>TODAY(),"Si","No") -> Si | AD7: 19202 | AE7: 19202 | AF7: 44480 | AG7: 7 | AH7: =EDATE(AF7,(AG7*12)-14) -> 46610 | AI7: =EDATE(AF7,(AG7*12)-12) -> 46671 | AJ7: =EDATE(AF7,AG7*12) -> 47037 | AM7: Res. 4837 de 07-abr-2014 (7a) Res. 2764 de 25-may-2007 | AN7: 3 | AR7: Si | AT7: ='Rutas AAC'!AE7
A8: 2 | B8: 34954 | C8: Facultad de Artes | D8: Maestría en Música | E8: Magíster en Música | F8: Ac. S. 071 17/12/2014 MODIFICADO por Ac. S. 022 6/04/2015 | G8: 104526 | I8: 20 (2021) | J8: Anual | N8: Popayán | O8: Diurna | P8: No | Q8: Maestría | R8: Posgrado | S8: Presencial | T8: Profundización | V8: 41 | W8: 41 | X8: 4 semestres | AB8: No se cuenta con información | AC8: =IF(AJ8>TODAY(),"Si","No") -> Si | AD8: 19204 | AE8: 19204 | AF8: 44480 | AG8: 7 | AH8: =EDATE(AF8,(AG8*12)-14) -> 46610 | AI8: =EDATE(AF8,(AG8*12)-12) -> 46671 | AJ8: =EDATE(AF8,AG8*12) -> 47037 | AM8: Res. 6930 de 14-may-2015 (7a) | AN8: 2 | AR8: No | AT8: ='Rutas AAC'!AE12
A9: 3 | B9: 13119 | C9: Facultad de Artes | D9: Licenciatura en Música | E9: Licenciado en Música | F9: Res. 1504 de 30-Jun-1992 CS | G9: 225 | I9: 25 (2023) | J9: Semestral | N9: Popayán | O9: Diurna | P9: No | Q9: Profesional Universitario | R9: Pregrado | S9: Presencial | T9: N/A | U9: N/A | V9: N/A | W9: 164 | X9: 10 Semestres | Y9: AC. 012 del 07-Jun-2017 (CA) | AA9: Res. 25125 de 17-nov-2017 (MEN) | AB9: 0.07 | AC9: =IF(AJ9>TODAY(),"Si","No") -> Si | AD9: 1042 | AE9: 1042 | AF9: 44960 | AG9: 7 | AH9: =EDATE(AF9,(AG9*12)-14) -> 47090 | AI9: =EDATE(AF9,(AG9*12)-12) -> 47152 | AJ9: =EDATE(AF9,AG9*12) -> 47517 | AM9: Res. 1999 de 13-feb-2018 (7a) Res. 743 de 08-feb-2011 (7a) Res. 2117 de 12-sep-2001 | AN9: 4 | AR9: Si | AS9: Si | AT9: ='Rutas AAC'!AE8 | AU9: 1042 | AV9: 44960 | AW9: 6 | AX9: =EDATE(AV9,(AW9*12)-14) -> 46724 | AY9: =EDATE(AV9,(AW9*12)-12) -> 46786 | AZ9: =EDATE(AV9,(AW9*12)) -> 47152 | BA9: =EDATE(AV9,((AW9/2)*12)) -> 46056 | BB9: Res. 27743 de 07-dic-2017 (4a) | BC9: 2
A10: 4 | B10: 31470 | C10: Facultad de Artes | D10: Música Instrumental | E10: Música Instrumental | F10: Ac. 046 de 29-Ago-2000 (CS) Modificado por el Acuerdo 008 de 2007 Derogado por el Ac. 038 de 11-Jun-2014 | G10: 54801 | I10: 30 (2023) | J10: Bimestral | N10: Popayán | O10: Diurna | P10: No | Q10: Profesional Universitario | R10: Pregrado | S10: Presencial | T10: N/A | U10: N/A | V10: N/A | W10: 182 | X10: 12 Semestres | Y10: AC. 015 del 2014 | AB10: No se cuenta con información | AC10: =IF(AJ10>TODAY(),"Si","No") -> Si | AD10: 1037 | AE10: 1037 | AF10: 44960 | AG10: 7 | AH10: =EDATE(AF10,(AG10*12)-14) -> 47090 | AI10: =EDATE(AF10,(AG10*12)-12) -> 47152 | AJ10: =EDATE(AF10,AG10*12) -> 47517 | AM10: Res. 8264 de 18-may-2021 (7a) Res. 18029 de 21-sep-2021 (Corr) Res. 13551 de 21-ago-2014 (7a) Res. 6506 de 26-oct-2007 | AN10: 4 | AR10: Si | AS10: Si | AT10: ='Rutas AAC'!AE11 | AU10: 1037 | AV10: 44960 | AW10: 6 | AX10: =EDATE(AV10,(AW10*12)-14) -> 46724 | AY10: =EDATE(AV10,(AW10*12)-12) -> 46786 | AZ10: =EDATE(AV10,(AW10*12)) -> 47152 | BA10: =EDATE(AV10,((AW10/2)*12)) -> 46056 | BC10: 1 | BE10: 2013
A11: 5 | B11: 31015 | C11: Facultad de Artes | D11: Diseño Gráfico | E11: Diseñador Gráfico | F11: Ac. 016 de 18-Feb-1997 CS | G11: 4963 | I11: 30 (2020) | J11: Semestral | N11: Popayán | O11: Diurna | P11: No | Q11: Profesional Universitario | R11: Pregrado | S11: Presencial | T11: N/A | U11: N/A | V11: N/A | W11: 149 | X11: 9 Semestres | Y11: AC. 014 del 21-Sep-2016 (CA) | AA11: Res. 04303 de 10-may-2017 MEN | AB11: No se cuenta con información | AC11: =IF(AJ11>TODAY(),"Si","No") -> Si | AD11: 6400 | AE11: 6400 | AF11: 45036 | AG11: 7 | AH11: =EDATE(AF11,(AG11*12)-14) -> 47169 | AI11: =EDATE(AF11,(AG11*12)-12) -> 47228 | AJ11: =EDATE(AF11,AG11*12) -> 47593 | AM11: Res. 12800 de 10-jul-2020 (7a) Res. 4938 de 07-abr-2014 (7a) Res. 4303 de 10-mar-2017 (Corr) Res. 5420 de 12-sep-2007 | AN11: 5 | AR11: Si | AS11: Si | AT11: ='Rutas AAC'!AE9 | AU11: 6400 | AV11: 45036 | AW11: 6 | AX11: =EDATE(AV11,(AW11*12)-14) -> 46803 | AY11: =EDATE(AV11,(AW11*12)-12) -> 46863 | AZ11: =EDATE(AV11,(AW11*12)) -> 47228 | BA11: =EDATE(AV11,((AW11/2)*12)) -> 46132 | BC11: 1
A12: 6 | B12: 31214 | C12: Facultad de Artes | D12: Dirección de Banda | E12: Maestro en Dirección de Banda | F12: Ac.045 de 29-Ago-2000 (Maestro en Música) (CS) | G12: 11067 | I12: 30 (2021) | J12: Anual | N12: Popayán | O12: Diurna | P12: No | Q12: Profesional Universitario | R12: Pregrado | S12: Presencial | T12: N/A | U12: N/A | V12: N/A | W12: 170 | X12: 10 Semestres | AB12: No se cuenta con información | AC12: =IF(AJ12>TODAY(),"Si","No") -> Si | AD12: 6402 | AE12: 6402 | AF12: 45036 | AG12: 7 | AH12: =EDATE(AF12,(AG12*12)-14) -> 47169 | AI12: =EDATE(AF12,(AG12*12)-12) -> 47228 | AJ12: =EDATE(AF12,AG12*12) -> 47593 | AM12: Res. 8914 de 21-may-2021 (7a) Res. 13547 de 21-ago-2014 (7a) Res. 5811 de 02-oct-2007 | AN12: 4 | AR12: Si | AS12: Si | AT12: ='Rutas AAC'!AE10 | AU12: 6402 | AV12: 45036 | AW12: 4 | AX12: =EDATE(AV12,(AW12*12)-14) -> 46073 | AY12: =EDATE(AV12,(AW12*12)-12) -> 46132 | AZ12: =EDATE(AV12,(AW12*12)) -> 46497 | BA12: =EDATE(AV12,((AW12/2)*12)) -> 45767 | BC12: 1
A13: 7 | B13: 21442 | C13: Facultad de Ciencias Agrarias | D13: Ingeniería Agroindustrial | E13: Ingeniero Agroindustrial | F13: Ac. 040 de 02-Nov-1995 Consejo Superior | G13: 3833 | I13: 40 (2020) | J13: Semestral | N13: Popayán Patía (El Bordo) Santander de Quilichao | O13: Diurna | P13: Ampliación de cobertura | Q13: Profesional Universitario | R13: Pregrado | S13: Presencial | T13: N/A | U13: N/A | V13: N/A | W13: 166 | X13: 10 Semestres | Y13: AC. 007 del 26-Mar-2012 (CA) AC. 020 del 26-Jun-2013 (CA) AC. 019 del 23-Sep-2015 (CA) | AB13: No se cuenta con información | AC13: =IF(AJ13>TODAY(),"Si","No") -> Si | AD13: 13200 | AE13: 13200 | AF13: 44029 | AG13: 7 | AH13: =EDATE(AF13,(AG13*12)-14) -> 46159 | AI13: =EDATE(AF13,(AG13*12)-12) -> 46220 | AJ13: =EDATE(AF13,AG13*12) -> 46585 | AM13: Res. 10608 de 14-jul-2015 Res. 5518 de 24-mar-2017 (Ren oficio) Res. 12939 de 31-dic-2010 Res. 1017 de 21-abr-2004 | AN13: 4 | AR13: Si | AS13: Si | AT13: ='Rutas AAC'!AE14 | AU13: 13200 | AV13: 44029 | AW13: 6 | AX13: =EDATE(AV13,(AW13*12)-14) -> 45794 | AY13: =EDATE(AV13,(AW13*12)-12) -> 45855 | AZ13: =EDATE(AV13,(AW13*12)) -> 46220 | BA13: =EDATE(AV13,((AW13/2)*12)) -> 45124 | BB13: Res. 10608 de 14-jul-2015 (4a) | BC13: 1 | BE13: 2013 | BF13: En la respuesta 2025-ER-0340850 de 18/08/2025 se indica que los municipios de Santander de Quilicihao y el Bordo no se encuentra registrados en el SNIES 3833
A14: 8 | B14: 32096 | C14: Facultad de Ciencias Agrarias / eliminar??? No enviamos correo NBC | D14: Especialización en Sanidad en Producción Agraria Integrada | E14: Especialista en Sanidad en Producción Agraria Integrada | F14: Ac. S. 005 6-feb-2014 | G14: 103292 | I14: 24 (2021) | J14: Semestral | N14: Popayán | O14: Diurna | P14: No | Q14: Especialización | R14: Posgrado | S14: Presencial | T14: Profundización | U14: N/A | V14: 27 | W14: 27 | X14: 2 semestres | AB14: 0.25 | AC14: =IF(AJ14>TODAY(),"Si","No") -> Si | AD14: 3293 | AE14: 3293 | AF14: 44258 | AG14: 7 | AH14: =EDATE(AF14,(AG14*12)-14) -> 46390 | AI14: =EDATE(AF14,(AG14*12)-12) -> 46449 | AJ14: =EDATE(AF14,AG14*12) -> 46815 | AM14: Res. 5444 de 14-abr-2014 (7a) | AN14: 2 | AR14: N/A | AT14: ='Rutas AAC'!AE19 | AU14: N/A | AV14: N/A | AW14: N/A | AX14: N/A | AY14: N/A | AZ14: N/A
A15: 9 | B15: 35059 | C15: Facultad de Ciencias Agrarias | D15: Especialización en Gestión Integral del Recurso Hídrico | E15: Especialista en Gestión Integral del Recurso Hídrico | F15: Ac. S. 057 19/11/2014 | G15: 104846 | I15: 21 (2022) | J15: Semestral | N15: Popayán | O15: Mixta | P15: No | Q15: Especialización | R15: Posgrado | S15: Presencial | T15: Profundización | U15: N/A | V15: 27 | W15: 27 | X15: 2 semestres | AB15: 0.25 | AC15: =IF(AJ15>TODAY(),"Si","No") -> Si | AD15: 2116 | AE15: 2116 | AF15: 44617 | AG15: 7 | AH15: =EDATE(AF15,(AG15*12)-14) -> 46746 | AI15: =EDATE(AF15,(AG15*12)-12) -> 46808 | AJ15: =EDATE(AF15,AG15*12) -> 47174 | AM15: Res. 12925 de 21-ago-2015 (7a) | AN15: 2 | AR15: N/A | AT15: ='Rutas AAC'!AE25 | AU15: N/A | AV15: N/A | AW15: N/A | AX15: N/A | AY15: N/A | AZ15: N/A
A17: 11 | B17: 35717 | C17: Facultad de Ciencias Agrarias | D17: Maestría en Ciencias Agrarias | E17: Magíster en Ciencias Agrarias | F17: Ac. S. 017 18/03/2015 | G17: 104677 | I17: 15 (2022) | J17: Anual | N17: Popayán | O17: Diurna | P17: No | Q17: Maestría | R17: Posgrado | S17: Presencial | T17: Investigación | U17: 52 | V17: N/A | W17: 52 | X17: 4 semestres | AB17: 0.25 | AC17: =IF(AJ17>TODAY(),"Si","No") -> Si | AD17: 9952 | AE17: 9952 | AF17: 44715 | AG17: 7 | AH17: =EDATE(AF17,(AG17*12)-14) -> 46846 | AI17: =EDATE(AF17,(AG17*12)-12) -> 46907 | AJ17: =EDATE(AF17,AG17*12) -> 47272 | AM17: Res. 9745 de 06-jul-2015 (7a) | AN17: 2 | AR17: No | AT17: ='Rutas AAC'!AE23
A18: 12 | B18: 29057 | C18: Facultad de Ciencias Agrarias | D18: Doctorado en Ciencias Agrarias y Agroindustriales | E18: Doctor en Ciencias Agrarias y Agroindustriales | F18: Ac. S. 020 23-abr-2013 | G18: 103231 | I18: 5 (2022) | J18: Anual | N18: Popayán | O18: Diurna | P18: No | Q18: Doctorado | R18: Posgrado | S18: Presencial | T18: Investigación | U18: 130 | V18: N/A | W18: 130 | X18: 8 semestres | AB18: 0.25 | AC18: =IF(AJ18>TODAY(),"Si","No") -> Si | AD18: 12973 | AE18: 12973 | AF18: 44748 | AG18: 7 | AH18: =EDATE(AF18,(AG18*12)-14) -> 46879 | AI18: =EDATE(AF18,(AG18*12)-12) -> 46940 | AJ18: =EDATE(AF18,AG18*12) -> 47305 | AM18: Res. 5533 de 14-abr-2014 (7a) Res. 8105 de 30-may-2014 (Correc) | AN18: 3 | AR18: No | AT18: ='Rutas AAC'!AE18
A19: 13 | B19: 21910 | C19: Facultad de Ciencias Agrarias | D19: Ingeniería Forestal | E19: Ingeniero Forestal | F19: Ac. 040 de 10-Sep-1999 CS | G19: 9833 | I19: 40 (2018) | J19: Semestral | N19: Popayán | O19: Diurna | P19: No | Q19: Profesional Universitario | R19: Pregrado | S19: Presencial | T19: N/A | U19: N/A | V19: N/A | W19: 157 | X19: 10 Semestres | Y19: AC. 007 del 26-Mar-2012 (CA) AC. 029 del 06-Ago-2013 (CA) | AA19: Res. 02948 del 22-02-2018 | AB19: 0.2 | AC19: =IF(AJ19>TODAY(),"Si","No") -> Si | AD19: 8482 | AE19: =AD19 -> 8482 | AF19: 45771 | AG19: 7 | AH19: =EDATE(AF19,(AG19*12)-14) -> 47903 | AI19: =EDATE(AF19,(AG19*12)-12) -> 47962 | AJ19: =EDATE(AF19,AG19*12) -> 48328 | AM19: Res. 4952 de 16-jun-11 Res. 1845 de 02-jul-2004 (7a) | AN19: 3 | AR19: Si | AS19: si | AT19: ='Rutas AAC'!AE16 | AU19: 8482 | AV19: 45771 | AW19: 6 | AX19: =EDATE(AV19,(AW19*12)-14) -> 47538 | AY19: =EDATE(AV19,(AW19*12)-12) -> 47597 | AZ19: =EDATE(AV19,(AW19*12)) -> 47962 | BA19: =EDATE(AV19,((AW19/2)*12)) -> 46867 | BC19: 1 | BE19: 2018 | BF19: Los nombres de estos programas fueron modificados mediante Ac. No. 9 20/02/1996. | BG19: Cristina Madiedo Pérez
A20: 14 | B20: 22635 | C20: Facultad de Ciencias Contables, Económicas y Administrativas | D20: Contaduría Pública | E20: Contador Público | F20: Ac. 065 de 03-Jul-1967 Ac 114 de 1966 | G20: 235 | I20: 46 (2018) 45 (2025) | J20: Semestral | N20: Popayán | O20: Nocturna | P20: No | Q20: Profesional Universitario | R20: Pregrado | S20: Presencial | T20: N/A | U20: N/A | V20: N/A | W20: 160 | X20: 10 Semestres | Y20: Res. 010 del 08-Feb-2012 (CA) AC. 001 del 2015 | AA20: Res. 14447 de 04-sep-2014 (MEN) Res. 16342 de 30-sep-2015 (MEN) | AB20: 0.0375 | AC20: =IF(AJ20>TODAY(),"Si","No") -> Si | AD20: 23503 | AE20: 23503 | AF20: 45989 | AG20: 7 | AH20: =EDATE(AJ20,-14) -> 48119 | AI20: =EDATE(AJ20,-12) -> 48180 | AJ20: =EDATE(AF20,AG20*12) -> 48546 | AL20: 46022 | AM20: Res. 8937 de 31-may-2018 (RenOficio) Res. 9871 de 20-may-2016 (7a) Res. 5680 de 25-ago-2009 Res. 16342 de 30-sep-2015 (Modif) Res. 8557 de 8-jul-2013 (Amp.Cob) Res. 1589 de 28-feb-2011 (7a) Res. 9772 de 23-dic-2008 (7a) Res. 23503 de 28-nov-2025 (7a) | AN20: 8 | AO20: Si | AR20: Si | AS20: No | AT20: ='Rutas AAC'!AE29 | BB20: Res. 5608 de 25-ago-2009 (4a) Res.464 de 20-feb-2004 (3a) | BC20: 3
A21: 15 | B21: 26485 | C21: Facultad de Ciencias Contables, Económicas y Administrativas | D21: Especialización en Gerencia de Impuestos | E21: Especialista en Gerencia de Impuestos | F21: Ac. S. 008 28/01/1994 | G21: 2970 | I21: 25 (2019) | J21: Semestral | N21: Popayán | O21: Diurna | P21: No | Q21: Especialización | R21: Posgrado | S21: Presencial | T21: Profundización | U21: N/A | V21: 26 | W21: 26 | X21: 2 Semestres | AB21: No se cuenta con información | AC21: =IF(AJ21>TODAY(),"Si","No") -> Si | AD21: 16033 | AE21: 16033 | AF21: 43817 | AG21: 7 | AH21: =EDATE(AF21,(AG21*12)-14) -> 45948 | AI21: =EDATE(AF21,(AG21*12)-12) -> 46009 | AJ21: =EDATE(AF21,AG21*12) -> 46374 | AM21: Res. 2571 de 14-mar-2013 (7a) Res. 2993 de 22-may-2008 | AN21: 3 | AR21: N/A | AT21: ='Rutas AAC'!AE30 | AU21: N/A | AV21: N/A | AW21: N/A | AX21: N/A | AY21: N/A | AZ21: N/A
A22: 16 | B22: 26543 | C22: Facultad de Ciencias Contables, Económicas y Administrativas | D22: Especialización en Revisoría Fiscal y Auditoría Internacional | E22: Especialista en Revisoría Fiscal y Auditoría Internacional | F22: Ac. S. 043 11/09/2001 | G22: 15924 | I22: 30 (2019) | J22: Semestral | N22: Popayán | O22: Diurna | P22: No | Q22: Especialización | R22: Posgrado | S22: Presencial | T22: Profundización | U22: N/A | V22: 28 | W22: 28 | X22: 2 Semestres | AB22: 0.25 | AC22: =IF(AJ22>TODAY(),"Si","No") -> Si | AD22: 16039 | AE22: 16039 | AF22: 43817 | AG22: 7 | AH22: =EDATE(AF22,(AG22*12)-14) -> 45948 | AI22: =EDATE(AF22,(AG22*12)-12) -> 46009 | AJ22: =EDATE(AF22,AG22*12) -> 46374 | AM22: Res. 4980 de 02-may-2013 (7a) Res. 17173 de 27-nov-2013 (Corr 4980) Res. 3193 de 30-may-2008 (5a) | AN22: 3 | AR22: N/A | AT22: ='Rutas AAC'!AE34 | AU22: N/A | AV22: N/A | AW22: N/A | AX22: N/A | AY22: N/A | AZ22: N/A
A23: 17 | B23: 25378 | C23: Facultad de Ciencias Contables, Económicas y Administrativas | D23: Especialización en Gerencia de Proyectos | E23: Especialista en Gerencia de Proyectos | F23: Ac. S. 033 8/08/1995 | G23: 102109 | I23: 30 (2019) | J23: Anual | K23: Si | L23: Universidad de Nariño | N23: Pasto - Nariño | O23: Mixta | P23: Si | Q23: Especialización | R23: Posgrado | S23: Presencial | T23: Profundización | U23: N/A | V23: 30 | W23: 30 | X23: 2 Semestres | AB23: No se cuenta con información | AC23: =IF(AJ23>TODAY(),"Si","No") -> Si | AD23: 16018 | AE23: 16018 | AF23: 43817 | AG23: 7 | AH23: =EDATE(AF23,(AG23*12)-14) -> 45948 | AI23: =EDATE(AF23,(AG23*12)-12) -> 46009 | AJ23: =EDATE(AF23,AG23*12) -> 46374 | AM23: Res. 16392 de 13-dic-2012 (7a) | AN23: 2 | AR23: N/A | AT23: ='Rutas AAC'!AE37 | AU23: N/A | AV23: N/A | AW23: N/A | AX23: N/A | AY23: N/A | AZ23: N/A
A24: 18 | B24: 28223 | C24: Facultad de Ciencias Contables, Económicas y Administrativas | D24: Especialización en Mercadeo Corporativo | E24: Especialista en Mercadeo Corporativo | F24: Res. 029 26/06/2001 | G24: 15358 | I24: 30 (2020) | J24: Semestral | N24: Popayán | O24: Diurna | P24: No | Q24: Especialización | R24: Posgrado | S24: Presencial | T24: Profundización | U24: N/A | V24: 19 | W24: 19 | X24: 2 Semestres | AB24: No se cuenta con información | AC24: =IF(AJ24>TODAY(),"Si","No") -> Si | AD24: 8266 | AE24: 8266 | AF24: 43978 | AG24: 7 | AH24: =EDATE(AF24,(AG24*12)-14) -> 46108 | AI24: =EDATE(AF24,(AG24*12)-12) -> 46169 | AJ24: =EDATE(AF24,AG24*12) -> 46534 | AM24: Res. 8951 de 15-jul-2013 (7a) Res. 7219 de 17-nov-2006 | AN24: 3 | AR24: N/A | AT24: ='Rutas AAC'!AE33 | AU24: N/A | AV24: N/A | AW24: N/A | AX24: N/A | AY24: N/A | AZ24: N/A
A25: 19 | B25: 26454 | C25: Facultad de Ciencias Contables, Económicas y Administrativas | D25: Especialización en Gerencia de Proyectos | E25: Especialista en Gerencia de Proyectos | F25: Ac. S. 033 08/08/1995 | G25: 3613 | I25: 35 (2020) | J25: Trimestral | N25: Popayán | O25: Mixta | P25: No | Q25: Especialización | R25: Posgrado | S25: Presencial | T25: Profundización | U25: N/A | V25: 30 | W25: 30 | X25: 2 Semestres | AB25: No se cuenta con información | AC25: =IF(AJ25>TODAY(),"Si","No") -> Si | AD25: 11104 | AE25: 11104 | AF25: 44012 | AG25: 7 | AH25: =EDATE(AF25,(AG25*12)-14) -> 46142 | AI25: =EDATE(AF25,(AG25*12)-12) -> 46203 | AJ25: =EDATE(AF25,AG25*12) -> 46568 | AM25: Res. 5358 de 10-may-2013 (7a) Res. 3192 de 30-may-2008 | AN25: 3 | AR25: N/A | AT25: ='[2]Rutas AAC'!AE45 -> #REF! | AU25: N/A | AV25: N/A | AW25: N/A | AX25: N/A | AY25: N/A | AZ25: N/A
A26: 20 | B26: 26638 | C26: Facultad de Ciencias Contables, Económicas y Administrativas | D26: Administración de Empresas | E26: Administrador de Empresas | F26: Res. 112 20-Dic-1989 CS | G26: 234 | I26: 45 (2020) | J26: Semestral | N26: Popayán | O26: Diurna | P26: No | Q26: Profesional Universitario | R26: Pregrado | S26: Presencial | T26: N/A | U26: N/A | V26: N/A | W26: 164 | X26: 10 Semestres | Y26: AC. 002 del 12-Feb-2014 (CA) | AA26: Res. 14130 de 02-sep-2014 (MEN) | AB26: No se cuenta con información | AC26: =IF(AJ26>TODAY(),"Si","No") -> Si | AD26: 18046 | AE26: 18046 | AF26: 44102 | AG26: 7 | AH26: =EDATE(AF26,(AG26*12)-14) -> 46231 | AI26: =EDATE(AF26,(AG26*12)-12) -> 46293 | AJ26: =EDATE(AF26,AG26*12) -> 46658 | AM26: Res. 575 de 22-ene-2018 (7a) Res. 14130 de 2-sep-2014 (Corr) Res 2031 de 24-mar-2010 (7a) Res 13153 de 16-oct-2012 Res. 17739 de 22-oct-2014 Res. 3152 de 16-jun-2006 | AN26: 3 | AR26: Si | AS26: No | AT26: ='Rutas AAC'!AE28 | BB26: Res. 20141 de 11-dic-2015 (4a) Res.2031 de 24-mar-2010 (4a) | BC26: 3 | BE26: 2013
A27: 21 | B27: 32323 | C27: Facultad de Ciencias Contables, Económicas y Administrativas | D27: Maestría en Gestión de Organizaciones y Proyectos | E27: Magíster en Gestión de Organizaciones y Proyectos | F27: Ac. S. 016 5/03/2014 | G27: 103477 | I27: 25 (2021) | J27: Anual | N27: Popayán | O27: Mixta | P27: No | Q27: Maestría | R27: Posgrado | S27: Presencial | T27: Investigación | U27: 54 | V27: N/A | W27: 54 | X27: 4 semestres | AB27: 0.25 | AC27: =IF(AJ27>TODAY(),"Si","No") -> Si | AD27: 2583 | AE27: 2583 | AF27: 44246 | AG27: 7 | AH27: =EDATE(AF27,(AG27*12)-14) -> 46375 | AI27: =EDATE(AF27,(AG27*12)-12) -> 46437 | AJ27: =EDATE(AF27,AG27*12) -> 46802 | AM27: Res. 222 de 04-ene-2021 (modificada por la Res. 2583) Res. 11044 de 14-jul-2014 (7a) | AN27: 2 | AR27: No | AT27: ='Rutas AAC'!AE38
A28: 22 | B28: 57747 | C28: Facultad de Ciencias Contables, Económicas y Administrativas | D28: Maestría en Economía Regional y Políticas Públicas | E28: Magíster en Economía Regional y Políticas Públicas | F28: Ac. 050 de 23-Sep-2021 | G28: 110924 | I28: 15 (2022) | J28: Anual | N28: Popayán | O28: Mixta | P28: No | Q28: Maestría | R28: Posgrado | S28: Presencial | T28: Investigación | U28: 56 | V28: N/A | W28: 56 | X28: 4 Semestres | AB28: No se cuenta con información | AC28: Si | AD28: 2117 | AE28: 2117 | AF28: 44617 | AG28: 7 | AH28: =EDATE(AF28,(AG28*12)-14) -> 46746 | AI28: =EDATE(AF28,(AG28*12)-12) -> 46808 | AJ28: =EDATE(AF28,AG28*12) -> 47174 | AN28: 1 | AR28: No
A29: 23 | B29: 57748 | C29: Facultad de Ciencias Contables, Económicas y Administrativas | D29: Maestría en Gestión del Conocimiento y la Innovación | E29: Magíster en Gestión del Conocimiento y la Innovación | F29: A. S. 049 de 23-Sep-2021 | G29: 111151 | I29: 15 (2022) | J29: Anual | N29: Popayán | O29: Diurna | P29: No | Q29: Maestría | R29: Posgrado | S29: Presencial | T29: Investigación | U29: 48 | V29: N/A | W29: 48 | X29: 4 Semestres | AB29: No se cuenta con información | AC29: Si | AD29: 7139 | AE29: 7139 | AF29: 44678 | AG29: 7 | AH29: =EDATE(AF29,(AG29*12)-14) -> 46810 | AI29: =EDATE(AF29,(AG29*12)-12) -> 46870 | AJ29: =EDATE(AF29,AG29*12) -> 47235 | AN29: 1 | AR29: No
A30: 24 | B30: 26448 | C30: Facultad de Ciencias Contables, Económicas y Administrativas | D30: Economía | E30: Economista | F30: Ac.003 de 20-Ene-1998 CS | G30: 8441 | I30: 45 (2023) | J30: Semestral | N30: Popayán | O30: Diurna | P30: No | Q30: Profesional Universitario | R30: Pregrado | S30: Presencial | T30: N/A | U30: N/A | V30: N/A | W30: 176 | X30: 10 Semestres | Y30: AC. 007 del 2014 | AB30: No se cuenta con información | AC30: =IF(AJ30>TODAY(),"Si","No") -> Si | AD30: 8576 | AE30: 8576 | AF30: 45071 | AG30: 7 | AH30: =EDATE(AF30,(AG30*12)-14) -> 47202 | AI30: =EDATE(AF30,(AG30*12)-12) -> 47263 | AJ30: =EDATE(AF30,AG30*12) -> 47628 | AM30: Res. 3525 de 17-jul-2018 (7a) Res. 3141 de 04-abr-2013 Res. 2159 de 17-may-2006 | AN30: 4 | AR30: Si | AS30: Si | AT30: ='Rutas AAC'!AE32 | AU30: 8576 | AV30: 45071 | AW30: 4 | AX30: =EDATE(AV30,(AW30*12)-14) -> 46106 | AY30: =EDATE(AV30,(AW30*12)-12) -> 46167 | AZ30: =EDATE(AV30,(AW30*12)) -> 46532 | BA30: =EDATE(AV30,((AW30/2)*12)) -> 45802 | BB30: Res. 11561 de 17-jul-2018 (4a) | BC30: 2
A31: 25 | B31: 38549 | C31: Facultad de Ciencias Contables, Económicas y Administrativas | D31: Maestría en Estudios Interdisciplinarios del Desarrollo | E31: Magíster en Estudios Interdisciplinarios del Desarrollo | F31: Ac. S. 009 17/02/2009 | G31: 55045 | I31: 46 (2017) | J31: Anual | N31: Popayán | O31: Diurna | P31: No | Q31: Maestría | R31: Posgrado | S31: Presencial | T31: Profundización | U31: N/A | V31: 46 | W31: 46 | X31: 4 semestres | AB31: 0.3 | AC31: =IF(AJ31>TODAY(),"Si","No") -> Si | AD31: 16177 | AE31: 16177 | AF31: 45174 | AG31: 7 | AH31: =EDATE(AF31,(AG31*12)-14) -> 47304 | AI31: =EDATE(AJ31,-12) -> 47366 | AJ31: =EDATE(AF31,AG31*12) -> 47731 | AL31: 45838 | AM31: Res. 10089 de 11-dic-2009 Res. 24382 de 30 de diciembre de 2016 | AN31: 2 | AP31: Res. 7060 de 29-09-2009 (Negada) | AQ31: 34 | AR31: Si | AT31: ='Rutas AAC'!AE36 -> 2
A32: 26 | B32: 23122 | C32: Facultad de Ciencias Contables, Económicas y Administrativas | D32: Turismo | E32: Profesional en Turismo | F32: Ac. 041 de 10-Sep-1999 | G32: 18679 | I32: 45 (2018) | J32: Semestral | N32: Popayán | O32: Mixta | P32: No | Q32: Profesional Universitario | R32: Pregrado | S32: Presencial | T32: N/A | U32: N/A | V32: N/A | W32: 177 | X32: 10 Semestres | AB32: 0.2 | AC32: =IF(AJ32>TODAY(),"Si","No") -> Si | AD32: 11924 | AE32: 11924 | AF32: 45820 | AG32: 7 | AH32: =EDATE(AF32,(AG32*12)-14) -> 47950 | AI32: =EDATE(AF32,(AG32*12)-12) -> 48011 | AJ32: =EDATE(AF32,AG32*12) -> 48377 | AM32: Res. 10587 de 22-nov-2011 (7a) Res. 5396 de 22-nov-2005 | AN32: 3 | AR32: No | AT32: ='Rutas AAC'!AE35 | BE32: 2013
A33: 27 | B33: 52824 | C33: Facultad de Ciencias de la Salud | D33: Maestría en Desarrollo Humano y Salud | E33: Magíster en Desarrollo Humano y Salud | F33: Ac. 084 de 27/11/2019 (CS) | G33: 110739 | I33: 30 (2021) | J33: Por cohorte | N33: Popayán | O33: Diurna | P33: No | Q33: Maestría | R33: Posgrado | S33: Presencial | T33: Investigación | U33: 40 | V33: N/A | W33: 40 | X33: 4 semestres | AB33: 0.5 | AC33: Si | AD33: 19531 | AE33: 19531 | AF33: 44488 | AG33: 7 | AH33: =EDATE(AF33,(AG33*12)-14) -> 46618 | AI33: =EDATE(AF33,(AG33*12)-12) -> 46679 | AJ33: =EDATE(AF33,AG33*12) -> 47045 | AN33: 1 | AR33: No
A34: 28 | B34: 28918 | C34: Facultad de Ciencias de la Salud | D34: Fonoaudiología | E34: Fonoaudiólogo (a) | F34: Res. 051 de 09-Sep-1997 | G34: 5268 | I34: 40 (2022) | J34: Semestral | N34: Popayán | O34: Diurna | P34: No | Q34: Profesional Universitario | R34: Pregrado | S34: Presencial | T34: N/A | U34: N/A | V34: N/A | W34: 174 | X34: 10 Semestres | AA34: Res. 16966 de 27-dic-2019 (MEN) | AB34: No se cuenta con información | AC34: =IF(AJ34>TODAY(),"Si","No") -> Si | AD34: 12529 | AE34: 12529 | AF34: 44742 | AG34: 7 | AH34: =EDATE(AF34,(AG34*12)-14) -> 46873 | AI34: =EDATE(AF34,(AG34*12)-12) -> 46934 | AJ34: =EDATE(AF34,AG34*12) -> 47299 | AM34: Res. 12304 de 08-jul-2021 (Negación) Res. 3454 de 14-mar-2014 (7a) Res. 905 de 28-feb-2007 | AN34: 4 | AR34: Si | AS34: Si | AT34: ='Rutas AAC'!AE55 -> 13 | BE34: 2013
A35: 29 | B35: 29652 | C35: Facultad de Ciencias de la Salud | D35: Especialización en Anestesiología | E35: Especialista en Anestesiología | F35: 1977 | G35: 240 | I35: 3 (2022) | J35: Anual | N35: Popayán | O35: Diurna | P35: No | Q35: Especialización | R35: Posgrado | S35: Presencial | T35: Profundización | U35: N/A | V35: 185 | W35: 185 | X35: 3 Años | AB35: 0.18 | AC35: =IF(AJ35>TODAY(),"Si","No") -> Si | AD35: 15518 | AE35: 15518 | AF35: 44777 | AG35: 7 | AH35: =EDATE(AF35,(AG35*12)-14) -> 46908 | AI35: =EDATE(AF35,(AG35*12)-12) -> 46969 | AJ35: =EDATE(AF35,AG35*12) -> 47334 | AM35: Res. 78 de 03-ene-2014 (7a) Res. 3436 de 28-may-2009 (5a) | AN35: 3 | AQ35: 73 | AR35: Si | AT35: ='[3]Rutas AAC'!AE46 -> #REF!
A36: 30 | B36: 29619 | C36: Facultad de Ciencias de la Salud | D36: Especialización en Pediatría | E36: Especialista en Pediatría | F36: 1975 | G36: 244 | I36: 4 (2022) | J36: Anual | N36: Popayán | O36: Diurna | P36: No | Q36: Especialización | R36: Posgrado | S36: Presencial | T36: Profundización | U36: N/A | V36: 166 | W36: 166 | X36: 3 Años | AB36: 0.15 | AC36: =IF(AJ36>TODAY(),"Si","No") -> Si | AD36: 15502 | AE36: 15502 | AF36: 44777 | AG36: 7 | AH36: =EDATE(AF36,(AG36*12)-14) -> 46908 | AI36: =EDATE(AF36,(AG36*12)-12) -> 46969 | AJ36: =EDATE(AF36,AG36*12) -> 47334 | AM36: Res. 172 de 03-ene-2014 (7a) Res. 2811 de 14-may-2009 (5a) | AN36: 3 | AQ36: 112 | AR36: Si | AT36: ='[3]Rutas AAC'!AE50 -> #REF!
A37: 31 | B37: 29249 | C37: Facultad de Ciencias de la Salud | D37: Especialización en Ginecología y Obstetricia | E37: Especialista en Ginecología y Obstetricia | F37: 1975 | G37: 242 | I37: 3 (2023) | J37: Anual | N37: Popayán | O37: Diurna | P37: No | Q37: Especialización | R37: Posgrado | S37: Presencial | T37: Profundización | U37: N/A | V37: 185 | W37: 185 | X37: 3 Años | AB37: 0.15 | AC37: Si | AD37: 3736 | AE37: 3736 | AF37: 44988 | AG37: 7 | AH37: =EDATE(AF37,(AG37*12)-14) -> 47121 | AI37: =EDATE(AF37,(AG37*12)-12) -> 47180 | AJ37: =EDATE(AF37,AG37*12) -> 47545 | AM37: Res. 4137 de 24-mar-2022 (Negación Rep.) Res. 25080 de 29-dic-2021 (Negación) Res. 477 de 16-ene-2014 (7a) Res. 1592 de 24-mar-2009 (5a) | AN37: 5 | AQ37: 106 | AR37: Si
A38: 32 | B38: 29653 | C38: Facultad de Ciencias de la Salud | D38: Especialización en Cirugía General | E38: Especialista en Cirugía General | F38: 1975 | G38: 241 | I38: 4 (2023) | J38: Anual | N38: Popayán | O38: Diurna | P38: No | Q38: Especialización | R38: Posgrado | S38: Presencial | T38: Profundización | U38: N/A | V38: 194 | W38: 194 | X38: 4 Años | AB38: 0.2 | AC38: =IF(AJ38>TODAY(),"Si","No") -> Si | AD38: 5523 | AE38: 5523 | AF38: 45021 | AG38: 7 | AH38: =EDATE(AF38,(AG38*12)-14) -> 47154 | AI38: =EDATE(AF38,(AG38*12)-12) -> 47213 | AJ38: =EDATE(AF38,AG38*12) -> 47578 | AM38: Res. 5943 de 19-abr-2022 (Negación) Res. 174 de 03-ene-2014 (7a) Res. 2810 de 14-may-2009 (5a) | AN38: 4 | AQ38: 46 | AR38: Si
A39: 33 | B39: 34165 | C39: Facultad de Ciencias de la Salud | D39: Enfermería | E39: Enfermera(o) | F39: Ac. 05 de 23-Jul-1970 CA | G39: 230 | I39: 35 (2023) | J39: Semestral | N39: Popayán | O39: Diurna | P39: No | Q39: Profesional Universitario | R39: Pregrado | S39: Presencial | T39: N/A | U39: N/A | V39: N/A | W39: 160 | X39: 10 Semestres | Y39: AC. 024 del 26-Jun-2013 (CA) AC. 004 del 18-Mar-2014 (CA) AC. 013 del 07-Jun-2017 (CA) | AB39: 0.15 | AC39: =IF(AJ39>TODAY(),"Si","No") -> Si | AD39: 14238 | AE39: 14238 | AF39: 45161 | AG39: 7 | AH39: =EDATE(AF39,(AG39*12)-14) -> 47292 | AI39: =EDATE(AF39,(AG39*12)-12) -> 47353 | AJ39: =EDATE(AF39,AG39*12) -> 47718 | AM39: Res. 10878 de 15-jun-2022 (Negación) Res. 2409 de 10-feb-2016 (7a) Res. 29544 de 29-dic-2017 (Modif) Res. 13927 de 29-ago-2014 (Modif) Res. 10573 de 23-dic-2009 (7a) | AN39: 6 | AR39: Si | AS39: Si | AT39: ='Rutas AAC'!AE48 | AU39: 14238 | AV39: 45161 | AW39: 6 | AX39: =EDATE(AV39,(AW39*12)-14) -> 46927 | AY39: =EDATE(AV39,(AW39*12)-12) -> 46988 | AZ39: =EDATE(AV39,(AW39*12)) -> 47353 | BA39: =EDATE(AV39,((AW39/2)*12)) -> 46257 | BB39: Res. 3572 de 16-jun-2008 (4a) Res. 3422 29-dic-2003 (3a) | BC39: 2 | BE39: 2013
A40: 34 | B40: 38315 | C40: Facultad de Ciencias de la Salud | D40: Especialización en Intervención del Lenguaje Infantil | E40: Especialista en Intervención del Lenguaje Infantil | F40: Res. 069 9/12/2015 | G40: 105964 | I40: 25 (2023) | J40: Anual | N40: Popayán | O40: Diurna | P40: No | Q40: Especialización | R40: Posgrado | S40: Presencial | T40: Profundización | U40: N/A | V40: 24 | W40: 24 | X40: 2 semestres | AB40: 0.25 | AC40: =IF(AJ40>TODAY(),"Si","No") -> Si | AD40: 9994 | AE40: 9994 | AF40: 45099 | AG40: 7 | AH40: =EDATE(AF40,(AG40*12)-14) -> 47230 | AI40: =EDATE(AF40,(AG40*12)-12) -> 47291 | AJ40: =EDATE(AF40,AG40*12) -> 47656 | AM40: Res. 20884 del 03-nov-2016 (7a) | AN40: 2 | AR40: N/A | AT40: ='Rutas AAC'!AE60 | AU40: N/A | AV40: N/A | AW40: N/A | AX40: N/A | AY40: N/A | AZ40: N/A
A41: 35 | B41: 57546 | C41: Facultad de Ciencias de la Salud | D41: Especialización en Medicina Interna | E41: Especialista en Medicina Interna | F41: 1962 | G41: 243 | I41: 4 (2023) | J41: Anual | N41: Popayán | O41: Diurna | P41: No | Q41: Especialización | R41: Posgrado | S41: Presencial | T41: Profundización | U41: N/A | V41: 185 | W41: 185 | X41: 3 años | Y41: AC. 015 del 2014 RES. 076 del 20-Oct-2016 (CA) | AB41: 0.2 | AC41: SI | AD41: 10592 | AE41: 10592 | AF41: 45106 | AG41: 7 | AH41: =EDATE(AF41,(AG41*12)-14) -> 47237 | AI41: =EDATE(AF41,(AG41*12)-12) -> 47298 | AJ41: =EDATE(AF41,AG41*12) -> 47663 | AM41: Res. 010815 de 13-jun-2022 (Negación) Res. 1591 de 24-mar-2009 (5a) | AN41: 2 | AQ41: 110 | AR41: SÍ
A42: 36 | B42: 57547 | C42: Facultad de Ciencias de la Salud | D42: Especialización en Medicina Familiar | E42: Especialista en Medicina Familiar | F42: Res. 025 12/05/1998 | G42: 11546 | I42: 8 (2023) | J42: Anual | N42: Popayán | O42: Diurna | P42: No | Q42: Especialización | R42: Posgrado | S42: Presencial | T42: Profundización | U42: N/A | V42: 147 | W42: 147 | X42: 3 años | Y42: RES. 003 del 15-Ene-2014 (CA) | AB42: No se cuenta con información | AC42: si | AD42: 10593 | AE42: 10593 | AF42: 45106 | AG42: 7 | AH42: =EDATE(AF42,(AG42*12)-14) -> 47237 | AI42: =EDATE(AF42,(AG42*12)-12) -> 47298 | AJ42: =EDATE(AF42,AG42*12) -> 47663 | AM42: Res. 10575 de 23-dic-2009 | AN42: 2 | AP42: Res. 010816 de 13-junio-2022 (Negada) Res. 6939 de 14-may-2015 (Negada) | AR42: No
...

Sheet Alerta de vencimiento
A1: Número | B1: Programa | C1: Vencimiento R.C. | D1: Alerta R.C. | E1: Días R.C | F1: Vencimiento SIAC RRC | G1: Alerta SIAC RRC | H1: Días SIAC RRC | I1: Observaciones
A2: =Consolidado!A16 -> 0 | B2: =Consolidado!D16 -> 0 | C2: =Consolidado!AJ16 -> 0 | D2: =_xludf.LET( _xlpm.h, TODAY(), IF(ISBLANK(C2), "SIN FECHA", _xludf.LET( _xlpm.dC, C2 - _xlpm.h, _xlpm.fC, IF(_xlpm.dC>=0, _xlpm.dC, 99999), IF(_xlpm.fC=99999, "YA SE VENCIÓ", "EL VENCIMIENTO DE RC se vence en " & _xlpm.fC & " días" ) ) ) ) -> #NAME? | E2: =_xludf.LET( _xlpm.m, C2 - TODAY(), _xlpm.m ) -> #NAME? | F2: =Consolidado!AH16 -> 0 | G2: =_xludf.LET( _xlpm.h, TODAY(), IF(ISBLANK(F2), "SIN FECHA", _xludf.LET( _xlpm.dC, F2 - _xlpm.h, _xlpm.fC, IF(_xlpm.dC>=0, _xlpm.dC, 99999), IF(_xlpm.fC=99999, "YA SE VENCIÓ", "EL VENCIMIENTO DE RC se vence en " & _xlpm.fC & " días" ) ) ) ) -> #NAME? | H2: =_xludf.LET( _xlpm.m, F2 - TODAY(), _xlpm.m ) -> #NAME? | I2: Revisado 22 enero 2026 ok
A3: =Consolidado!A87 -> 81 | B3: =Consolidado!D87 -> Derecho | C3: =Consolidado!AJ87 -> 46261 | D3: =_xludf.LET( _xlpm.h, TODAY(), IF(ISBLANK(C3), "SIN FECHA", _xludf.LET( _xlpm.dC, C3 - _xlpm.h, _xlpm.fC, IF(_xlpm.dC>=0, _xlpm.dC, 99999), IF(_xlpm.fC=99999, "YA SE VENCIÓ", "EL VENCIMIENTO DE RC se vence en " & _xlpm.fC & " días" ) ) ) ) -> #NAME? | E3: =_xludf.LET( _xlpm.m, C3 - TODAY(), _xlpm.m ) -> #NAME? | F3: =Consolidado!AH87 -> 45835 | G3: =_xludf.LET( _xlpm.h, TODAY(), IF(ISBLANK(F3), "SIN FECHA", _xludf.LET( _xlpm.dC, F3 - _xlpm.h, _xlpm.fC, IF(_xlpm.dC>=0, _xlpm.dC, 99999), IF(_xlpm.fC=99999, "YA SE VENCIÓ", "EL VENCIMIENTO DE RC se vence en " & _xlpm.fC & " días" ) ) ) ) -> #NAME? | H3: =_xludf.LET( _xlpm.m, F3 - TODAY(), _xlpm.m ) -> #NAME?
A4: =Consolidado!A89 -> 83 | B4: =Consolidado!D89 -> Derecho | C4: =Consolidado!AJ89 -> 46262 | D4: =_xludf.LET( _xlpm.h, TODAY(), IF(ISBLANK(C4), "SIN FECHA", _xludf.LET( _xlpm.dC, C4 - _xlpm.h, _xlpm.fC, IF(_xlpm.dC>=0, _xlpm.dC, 99999), IF(_xlpm.fC=99999, "YA SE VENCIÓ", "EL VENCIMIENTO DE RC se vence en " & _xlpm.fC & " días" ) ) ) ) -> #NAME? | E4: =_xludf.LET( _xlpm.m, C4 - TODAY(), _xlpm.m ) -> #NAME? | F4: =Consolidado!AH89 -> 45836 | G4: =_xludf.LET( _xlpm.h, TODAY(), IF(ISBLANK(F4), "SIN FECHA", _xludf.LET( _xlpm.dC, F4 - _xlpm.h, _xlpm.fC, IF(_xlpm.dC>=0, _xlpm.dC, 99999), IF(_xlpm.fC=99999, "YA SE VENCIÓ", "EL VENCIMIENTO DE RC se vence en " & _xlpm.fC & " días" ) ) ) ) -> #NAME? | H4: =_xludf.LET( _xlpm.m, F4 - TODAY(), _xlpm.m ) -> #NAME?
A5: =Consolidado!A110 -> 104 | B5: =Consolidado!D110 -> Especialización en Redes y Servicios Telemáticos | C5: =Consolidado!AJ110 -> 46262 | D5: =_xludf.LET( _xlpm.h, TODAY(), IF(ISBLANK(C5), "SIN FECHA", _xludf.LET( _xlpm.dC, C5 - _xlpm.h, _xlpm.fC, IF(_xlpm.dC>=0, _xlpm.dC, 99999), IF(_xlpm.fC=99999, "YA SE VENCIÓ", "EL VENCIMIENTO DE RC se vence en " & _xlpm.fC & " días" ) ) ) ) -> #NAME? | E5: =_xludf.LET( _xlpm.m, C5 - TODAY(), _xlpm.m ) -> #NAME? | F5: =Consolidado!AH110 -> 45836 | G5: =_xludf.LET( _xlpm.h, TODAY(), IF(ISBLANK(F5), "SIN FECHA", _xludf.LET( _xlpm.dC, F5 - _xlpm.h, _xlpm.fC, IF(_xlpm.dC>=0, _xlpm.dC, 99999), IF(_xlpm.fC=99999, "YA SE VENCIÓ", "EL VENCIMIENTO DE RC se vence en " & _xlpm.fC & " días" ) ) ) ) -> #NAME? | H5: =_xludf.LET( _xlpm.m, F5 - TODAY(), _xlpm.m ) -> #NAME?
A6: =Consolidado!A111 -> 105 | B6: =Consolidado!D111 -> Especialización en Redes y Servicios Telemáticos | C6: =Consolidado!AJ111 -> 46366 | D6: =_xludf.LET( _xlpm.h, TODAY(), IF(ISBLANK(C6), "SIN FECHA", _xludf.LET( _xlpm.dC, C6 - _xlpm.h, _xlpm.fC, IF(_xlpm.dC>=0, _xlpm.dC, 99999), IF(_xlpm.fC=99999, "YA SE VENCIÓ", "EL VENCIMIENTO DE RC se vence en " & _xlpm.fC & " días" ) ) ) ) -> #NAME? | E6: =_xludf.LET( _xlpm.m, C6 - TODAY(), _xlpm.m ) -> #NAME? | F6: =Consolidado!AH111 -> 45940 | G6: =_xludf.LET( _xlpm.h, TODAY(), IF(ISBLANK(F6), "SIN FECHA", _xludf.LET( _xlpm.dC, F6 - _xlpm.h, _xlpm.fC, IF(_xlpm.dC>=0, _xlpm.dC, 99999), IF(_xlpm.fC=99999, "YA SE VENCIÓ", "EL VENCIMIENTO DE RC se vence en " & _xlpm.fC & " días" ) ) ) ) -> #NAME? | H6: =_xludf.LET( _xlpm.m, F6 - TODAY(), _xlpm.m ) -> #NAME?
A7: =Consolidado!A95 -> 89 | B7: =Consolidado!D95 -> Maestría en Ingeniería Hidráulica e Hidrológica | C7: =Consolidado!AJ95 -> 46373 | D7: =_xludf.LET( _xlpm.h, TODAY(), IF(ISBLANK(C7), "SIN FECHA", _xludf.LET( _xlpm.dC, C7 - _xlpm.h, _xlpm.fC, IF(_xlpm.dC>=0, _xlpm.dC, 99999), IF(_xlpm.fC=99999, "YA SE VENCIÓ", "EL VENCIMIENTO DE RC se vence en " & _xlpm.fC & " días" ) ) ) ) -> #NAME? | E7: =_xludf.LET( _xlpm.m, C7 - TODAY(), _xlpm.m ) -> #NAME? | F7: =Consolidado!AH95 -> 45947 | G7: =_xludf.LET( _xlpm.h, TODAY(), IF(ISBLANK(F7), "SIN FECHA", _xludf.LET( _xlpm.dC, F7 - _xlpm.h, _xlpm.fC, IF(_xlpm.dC>=0, _xlpm.dC, 99999), IF(_xlpm.fC=99999, "YA SE VENCIÓ", "EL VENCIMIENTO DE RC se vence en " & _xlpm.fC & " días" ) ) ) ) -> #NAME? | H7: =_xludf.LET( _xlpm.m, F7 - TODAY(), _xlpm.m ) -> #NAME?
A8: =Consolidado!A21 -> 15 | B8: =Consolidado!D21 -> Especialización en Gerencia de Impuestos | C8: =Consolidado!AJ21 -> 46374 | D8: =_xludf.LET( _xlpm.h, TODAY(), IF(ISBLANK(C8), "SIN FECHA", _xludf.LET( _xlpm.dC, C8 - _xlpm.h, _xlpm.fC, IF(_xlpm.dC>=0, _xlpm.dC, 99999), IF(_xlpm.fC=99999, "YA SE VENCIÓ", "EL VENCIMIENTO DE RC se vence en " & _xlpm.fC & " días" ) ) ) ) -> #NAME? | E8: =_xludf.LET( _xlpm.m, C8 - TODAY(), _xlpm.m ) -> #NAME? | F8: =Consolidado!AH21 -> 45948 | G8: =_xludf.LET( _xlpm.h, TODAY(), IF(ISBLANK(F8), "SIN FECHA", _xludf.LET( _xlpm.dC, F8 - _xlpm.h, _xlpm.fC, IF(_xlpm.dC>=0, _xlpm.dC, 99999), IF(_xlpm.fC=99999, "YA SE VENCIÓ", "EL VENCIMIENTO DE RC se vence en " & _xlpm.fC & " días" ) ) ) ) -> #NAME? | H8: =_xludf.LET( _xlpm.m, F8 - TODAY(), _xlpm.m ) -> #NAME?
A9: =Consolidado!A22 -> 16 | B9: =Consolidado!D22 -> Especialización en Revisoría Fiscal y Auditoría Internacional | C9: =Consolidado!AJ22 -> 46374 | D9: =_xludf.LET( _xlpm.h, TODAY(), IF(ISBLANK(C9), "SIN FECHA", _xludf.LET( _xlpm.dC, C9 - _xlpm.h, _xlpm.fC, IF(_xlpm.dC>=0, _xlpm.dC, 99999), IF(_xlpm.fC=99999, "YA SE VENCIÓ", "EL VENCIMIENTO DE RC se vence en " & _xlpm.fC & " días" ) ) ) ) -> #NAME? | E9: =_xludf.LET( _xlpm.m, C9 - TODAY(), _xlpm.m ) -> #NAME? | F9: =Consolidado!AH22 -> 45948 | G9: =_xludf.LET( _xlpm.h, TODAY(), IF(ISBLANK(F9), "SIN FECHA", _xludf.LET( _xlpm.dC, F9 - _xlpm.h, _xlpm.fC, IF(_xlpm.dC>=0, _xlpm.dC, 99999), IF(_xlpm.fC=99999, "YA SE VENCIÓ", "EL VENCIMIENTO DE RC se vence en " & _xlpm.fC & " días" ) ) ) ) -> #NAME? | H9: =_xludf.LET( _xlpm.m, F9 - TODAY(), _xlpm.m ) -> #NAME?
A10: =Consolidado!A23 -> 17 | B10: =Consolidado!D23 -> Especialización en Gerencia de Proyectos | C10: =Consolidado!AJ23 -> 46374 | D10: =_xludf.LET( _xlpm.h, TODAY(), IF(ISBLANK(C10), "SIN FECHA", _xludf.LET( _xlpm.dC, C10 - _xlpm.h, _xlpm.fC, IF(_xlpm.dC>=0, _xlpm.dC, 99999), IF(_xlpm.fC=99999, "YA SE VENCIÓ", "EL VENCIMIENTO DE RC se vence en " & _xlpm.fC & " días" ) ) ) ) -> #NAME? | E10: =_xludf.LET( _xlpm.m, C10 - TODAY(), _xlpm.m ) -> #NAME? | F10: =Consolidado!AH23 -> 45948 | G10: =_xludf.LET( _xlpm.h, TODAY(), IF(ISBLANK(F10), "SIN FECHA", _xludf.LET( _xlpm.dC, F10 - _xlpm.h, _xlpm.fC, IF(_xlpm.dC>=0, _xlpm.dC, 99999), IF(_xlpm.fC=99999, "YA SE VENCIÓ", "EL VENCIMIENTO DE RC se vence en " & _xlpm.fC & " días" ) ) ) ) -> #NAME? | H10: =_xludf.LET( _xlpm.m, F10 - TODAY(), _xlpm.m ) -> #NAME?
A11: =Consolidado!A46 -> 40 | B11: =Consolidado!D46 -> Licenciatura en Lenguas Modernas con énfasis en Inglés y Francés (Santander de Quilichao) | C11: =Consolidado!AJ46 -> 46374 | D11: =_xludf.LET( _xlpm.h, TODAY(), IF(ISBLANK(C11), "SIN FECHA", _xludf.LET( _xlpm.dC, C11 - _xlpm.h, _xlpm.fC, IF(_xlpm.dC>=0, _xlpm.dC, 99999), IF(_xlpm.fC=99999, "YA SE VENCIÓ", "EL VENCIMIENTO DE RC se vence en " & _xlpm.fC & " días" ) ) ) ) -> #NAME? | E11: =_xludf.LET( _xlpm.m, C11 - TODAY(), _xlpm.m ) -> #NAME? | F11: =Consolidado!AH46 -> 45948 | G11: =_xludf.LET( _xlpm.h, TODAY(), IF(ISBLANK(F11), "SIN FECHA", _xludf.LET( _xlpm.dC, F11 - _xlpm.h, _xlpm.fC, IF(_xlpm.dC>=0, _xlpm.dC, 99999), IF(_xlpm.fC=99999, "YA SE VENCIÓ", "EL VENCIMIENTO DE RC se vence en " & _xlpm.fC & " días" ) ) ) ) -> #NAME? | H11: =_xludf.LET( _xlpm.m, F11 - TODAY(), _xlpm.m ) -> #NAME?
A12: =Consolidado!A96 -> 90 | B12: =Consolidado!D96 -> Maestría en Ingeniería Ambiental | C12: =Consolidado!AJ96 -> 46383 | D12: =_xludf.LET( _xlpm.h, TODAY(), IF(ISBLANK(C12), "SIN FECHA", _xludf.LET( _xlpm.dC, C12 - _xlpm.h, _xlpm.fC, IF(_xlpm.dC>=0, _xlpm.dC, 99999), IF(_xlpm.fC=99999, "YA SE VENCIÓ", "EL VENCIMIENTO DE RC se vence en " & _xlpm.fC & " días" ) ) ) ) -> #NAME? | E12: =_xludf.LET( _xlpm.m, C12 - TODAY(), _xlpm.m ) -> #NAME? | F12: =Consolidado!AH96 -> 45957 | G12: =_xludf.LET( _xlpm.h, TODAY(), IF(ISBLANK(F12), "SIN FECHA", _xludf.LET( _xlpm.dC, F12 - _xlpm.h, _xlpm.fC, IF(_xlpm.dC>=0, _xlpm.dC, 99999), IF(_xlpm.fC=99999, "YA SE VENCIÓ", "EL VENCIMIENTO DE RC se vence en " & _xlpm.fC & " días" ) ) ) ) -> #NAME? | H12: =_xludf.LET( _xlpm.m, F12 - TODAY(), _xlpm.m ) -> #NAME?
A13: =Consolidado!A112 -> 106 | B13: =Consolidado!D112 -> Ingeniería Electrónica y Telecomunicaciones | C13: =Consolidado!AJ112 -> 46489 | D13: =_xludf.LET( _xlpm.h, TODAY(), IF(ISBLANK(C13), "SIN FECHA", _xludf.LET( _xlpm.dC, C13 - _xlpm.h, _xlpm.fC, IF(_xlpm.dC>=0, _xlpm.dC, 99999), IF(_xlpm.fC=99999, "YA SE VENCIÓ", "EL VENCIMIENTO DE RC se vence en " & _xlpm.fC & " días" ) ) ) ) -> #NAME? | E13: =_xludf.LET( _xlpm.m, C13 - TODAY(), _xlpm.m ) -> #NAME? | F13: =Consolidado!AH112 -> 46065 | G13: =_xludf.LET( _xlpm.h, TODAY(), IF(ISBLANK(F13), "SIN FECHA", _xludf.LET( _xlpm.dC, F13 - _xlpm.h, _xlpm.fC, IF(_xlpm.dC>=0, _xlpm.dC, 99999), IF(_xlpm.fC=99999, "YA SE VENCIÓ", "EL VENCIMIENTO DE RC se vence en " & _xlpm.fC & " días" ) ) ) ) -> #NAME? | H13: =_xludf.LET( _xlpm.m, F13 - TODAY(), _xlpm.m ) -> #NAME?
A14: =Consolidado!A24 -> 18 | B14: =Consolidado!D24 -> Especialización en Mercadeo Corporativo | C14: =Consolidado!AJ24 -> 46534 | D14: =_xludf.LET( _xlpm.h, TODAY(), IF(ISBLANK(C14), "SIN FECHA", _xludf.LET( _xlpm.dC, C14 - _xlpm.h, _xlpm.fC, IF(_xlpm.dC>=0, _xlpm.dC, 99999), IF(_xlpm.fC=99999, "YA SE VENCIÓ", "EL VENCIMIENTO DE RC se vence en " & _xlpm.fC & " días" ) ) ) ) -> #NAME? | E14: =_xludf.LET( _xlpm.m, C14 - TODAY(), _xlpm.m ) -> #NAME? | F14: =Consolidado!AH24 -> 46108 | G14: =_xludf.LET( _xlpm.h, TODAY(), IF(ISBLANK(F14), "SIN FECHA", _xludf.LET( _xlpm.dC, F14 - _xlpm.h, _xlpm.fC, IF(_xlpm.dC>=0, _xlpm.dC, 99999), IF(_xlpm.fC=99999, "YA SE VENCIÓ", "EL VENCIMIENTO DE RC se vence en " & _xlpm.fC & " días" ) ) ) ) -> #NAME? | H14: =_xludf.LET( _xlpm.m, F14 - TODAY(), _xlpm.m ) -> #NAME?
A15: =Consolidado!A47 -> 41 | B15: =Consolidado!D47 -> Filosofía | C15: =Consolidado!AJ47 -> 46534 | D15: =_xludf.LET( _xlpm.h, TODAY(), IF(ISBLANK(C15), "SIN FECHA", _xludf.LET( _xlpm.dC, C15 - _xlpm.h, _xlpm.fC, IF(_xlpm.dC>=0, _xlpm.dC, 99999), IF(_xlpm.fC=99999, "YA SE VENCIÓ", "EL VENCIMIENTO DE RC se vence en " & _xlpm.fC & " días" ) ) ) ) -> #NAME? | E15: =_xludf.LET( _xlpm.m, C15 - TODAY(), _xlpm.m ) -> #NAME? | F15: =Consolidado!AH47 -> 46108 | G15: =_xludf.LET( _xlpm.h, TODAY(), IF(ISBLANK(F15), "SIN FECHA", _xludf.LET( _xlpm.dC, F15 - _xlpm.h, _xlpm.fC, IF(_xlpm.dC>=0, _xlpm.dC, 99999), IF(_xlpm.fC=99999, "YA SE VENCIÓ", "EL VENCIMIENTO DE RC se vence en " & _xlpm.fC & " días" ) ) ) ) -> #NAME? | H15: =_xludf.LET( _xlpm.m, F15 - TODAY(), _xlpm.m ) -> #NAME?
A16: =Consolidado!A97 -> 91 | B16: =Consolidado!D97 -> Ingeniería Ambiental | C16: =Consolidado!AJ97 -> 46554 | D16: =_xludf.LET( _xlpm.h, TODAY(), IF(ISBLANK(C16), "SIN FECHA", _xludf.LET( _xlpm.dC, C16 - _xlpm.h, _xlpm.fC, IF(_xlpm.dC>=0, _xlpm.dC, 99999), IF(_xlpm.fC=99999, "YA SE VENCIÓ", "EL VENCIMIENTO DE RC se vence en " & _xlpm.fC & " días" ) ) ) ) -> #NAME? | E16: =_xludf.LET( _xlpm.m, C16 - TODAY(), _xlpm.m ) -> #NAME? | F16: =Consolidado!AH97 -> 46128 | G16: =_xludf.LET( _xlpm.h, TODAY(), IF(ISBLANK(F16), "SIN FECHA", _xludf.LET( _xlpm.dC, F16 - _xlpm.h, _xlpm.fC, IF(_xlpm.dC>=0, _xlpm.dC, 99999), IF(_xlpm.fC=99999, "YA SE VENCIÓ", "EL VENCIMIENTO DE RC se vence en " & _xlpm.fC & " días" ) ) ) ) -> #NAME? | H16: =_xludf.LET( _xlpm.m, F16 - TODAY(), _xlpm.m ) -> #NAME?
A17: =Consolidado!A25 -> 19 | B17: =Consolidado!D25 -> Especialización en Gerencia de Proyectos | C17: =Consolidado!AJ25 -> 46568 | D17: =_xludf.LET( _xlpm.h, TODAY(), IF(ISBLANK(C17), "SIN FECHA", _xludf.LET( _xlpm.dC, C17 - _xlpm.h, _xlpm.fC, IF(_xlpm.dC>=0, _xlpm.dC, 99999), IF(_xlpm.fC=99999, "YA SE VENCIÓ", "EL VENCIMIENTO DE RC se vence en " & _xlpm.fC & " días" ) ) ) ) -> #NAME? | E17: =_xludf.LET( _xlpm.m, C17 - TODAY(), _xlpm.m ) -> #NAME? | F17: =Consolidado!AH25 -> 46142 | G17: =_xludf.LET( _xlpm.h, TODAY(), IF(ISBLANK(F17), "SIN FECHA", _xludf.LET( _xlpm.dC, F17 - _xlpm.h, _xlpm.fC, IF(_xlpm.dC>=0, _xlpm.dC, 99999), IF(_xlpm.fC=99999, "YA SE VENCIÓ", "EL VENCIMIENTO DE RC se vence en " & _xlpm.fC & " días" ) ) ) ) -> #NAME? | H17: =_xludf.LET( _xlpm.m, F17 - TODAY(), _xlpm.m ) -> #NAME?
A18: =Consolidado!A48 -> 42 | B18: =Consolidado!D48 -> Geografía del Desarrollo Regional y Ambiental | C18: =Consolidado!AJ48 -> 46570 | D18: =_xludf.LET( _xlpm.h, TODAY(), IF(ISBLANK(C18), "SIN FECHA", _xludf.LET( _xlpm.dC, C18 - _xlpm.h, _xlpm.fC, IF(_xlpm.dC>=0, _xlpm.dC, 99999), IF(_xlpm.fC=99999, "YA SE VENCIÓ", "EL VENCIMIENTO DE RC se vence en " & _xlpm.fC & " días" ) ) ) ) -> #NAME? | E18: =_xludf.LET( _xlpm.m, C18 - TODAY(), _xlpm.m ) -> #NAME? | F18: =Consolidado!AH48 -> 46144 | G18: =_xludf.LET( _xlpm.h, TODAY(), IF(ISBLANK(F18), "SIN FECHA", _xludf.LET( _xlpm.dC, F18 - _xlpm.h, _xlpm.fC, IF(_xlpm.dC>=0, _xlpm.dC, 99999), IF(_xlpm.fC=99999, "YA SE VENCIÓ", "EL VENCIMIENTO DE RC se vence en " & _xlpm.fC & " días" ) ) ) ) -> #NAME? | H18: =_xludf.LET( _xlpm.m, F18 - TODAY(), _xlpm.m ) -> #NAME?
A19: =Consolidado!A13 -> 7 | B19: =Consolidado!D13 -> Ingeniería Agroindustrial | C19: =Consolidado!AJ13 -> 46585 | D19: =_xludf.LET( _xlpm.h, TODAY(), IF(ISBLANK(C19), "SIN FECHA", _xludf.LET( _xlpm.dC, C19 - _xlpm.h, _xlpm.fC, IF(_xlpm.dC>=0, _xlpm.dC, 99999), IF(_xlpm.fC=99999, "YA SE VENCIÓ", "EL VENCIMIENTO DE RC se vence en " & _xlpm.fC & " días" ) ) ) ) -> #NAME? | E19: =_xludf.LET( _xlpm.m, C19 - TODAY(), _xlpm.m ) -> #NAME? | F19: =Consolidado!AH13 -> 46159 | G19: =_xludf.LET( _xlpm.h, TODAY(), IF(ISBLANK(F19), "SIN FECHA", _xludf.LET( _xlpm.dC, F19 - _xlpm.h, _xlpm.fC, IF(_xlpm.dC>=0, _xlpm.dC, 99999), IF(_xlpm.fC=99999, "YA SE VENCIÓ", "EL VENCIMIENTO DE RC se vence en " & _xlpm.fC & " días" ) ) ) ) -> #NAME? | H19: =_xludf.LET( _xlpm.m, F19 - TODAY(), _xlpm.m ) -> #NAME?
A20: =Consolidado!A115 -> 109 | B20: =Consolidado!D115 -> Tecnología en Telemática | C20: =Consolidado!AJ115 -> 46585 | D20: =_xludf.LET( _xlpm.h, TODAY(), IF(ISBLANK(C20), "SIN FECHA", _xludf.LET( _xlpm.dC, C20 - _xlpm.h, _xlpm.fC, IF(_xlpm.dC>=0, _xlpm.dC, 99999), IF(_xlpm.fC=99999, "YA SE VENCIÓ", "EL VENCIMIENTO DE RC se vence en " & _xlpm.fC & " días" ) ) ) ) -> #NAME? | E20: =_xludf.LET( _xlpm.m, C20 - TODAY(), _xlpm.m ) -> #NAME? | F20: =Consolidado!AH115 -> 46159 | G20: =_xludf.LET( _xlpm.h, TODAY(), IF(ISBLANK(F20), "SIN FECHA", _xludf.LET( _xlpm.dC, F20 - _xlpm.h, _xlpm.fC, IF(_xlpm.dC>=0, _xlpm.dC, 99999), IF(_xlpm.fC=99999, "YA SE VENCIÓ", "EL VENCIMIENTO DE RC se vence en " & _xlpm.fC & " días" ) ) ) ) -> #NAME? | H20: =_xludf.LET( _xlpm.m, F20 - TODAY(), _xlpm.m ) -> #NAME?
A21: =Consolidado!A113 -> 107 | B21: =Consolidado!D113 -> Maestría en Ingeniería Telemática | C21: =Consolidado!AJ113 -> 46592 | D21: =_xludf.LET( _xlpm.h, TODAY(), IF(ISBLANK(C21), "SIN FECHA", _xludf.LET( _xlpm.dC, C21 - _xlpm.h, _xlpm.fC, IF(_xlpm.dC>=0, _xlpm.dC, 99999), IF(_xlpm.fC=99999, "YA SE VENCIÓ", "EL VENCIMIENTO DE RC se vence en " & _xlpm.fC & " días" ) ) ) ) -> #NAME? | E21: =_xludf.LET( _xlpm.m, C21 - TODAY(), _xlpm.m ) -> #NAME? | F21: =Consolidado!AH113 -> 46166 | G21: =_xludf.LET( _xlpm.h, TODAY(), IF(ISBLANK(F21), "SIN FECHA", _xludf.LET( _xlpm.dC, F21 - _xlpm.h, _xlpm.fC, IF(_xlpm.dC>=0, _xlpm.dC, 99999), IF(_xlpm.fC=99999, "YA SE VENCIÓ", "EL VENCIMIENTO DE RC se vence en " & _xlpm.fC & " días" ) ) ) ) -> #NAME? | H21: =_xludf.LET( _xlpm.m, F21 - TODAY(), _xlpm.m ) -> #NAME?
A22: =Consolidado!A99 -> 93 | B22: =Consolidado!D99 -> Especialización en Estructuras | C22: =Consolidado!AJ99 -> 46603 | D22: =_xludf.LET( _xlpm.h, TODAY(), IF(ISBLANK(C22), "SIN FECHA", _xludf.LET( _xlpm.dC, C22 - _xlpm.h, _xlpm.fC, IF(_xlpm.dC>=0, _xlpm.dC, 99999), IF(_xlpm.fC=99999, "YA SE VENCIÓ", "EL VENCIMIENTO DE RC se vence en " & _xlpm.fC & " días" ) ) ) ) -> #NAME? | E22: =_xludf.LET( _xlpm.m, C22 - TODAY(), _xlpm.m ) -> #NAME? | F22: =Consolidado!AH99 -> 46177 | G22: =_xludf.LET( _xlpm.h, TODAY(), IF(ISBLANK(F22), "SIN FECHA", _xludf.LET( _xlpm.dC, F22 - _xlpm.h, _xlpm.fC, IF(_xlpm.dC>=0, _xlpm.dC, 99999), IF(_xlpm.fC=99999, "YA SE VENCIÓ", "EL VENCIMIENTO DE RC se vence en " & _xlpm.fC & " días" ) ) ) ) -> #NAME? | H22: =_xludf.LET( _xlpm.m, F22 - TODAY(), _xlpm.m ) -> #NAME?
A23: =Consolidado!A114 -> 108 | B23: =Consolidado!D114 -> Doctorado en Ciencias de la Computación | C23: =Consolidado!AJ114 -> 46605 | D23: =_xludf.LET( _xlpm.h, TODAY(), IF(ISBLANK(C23), "SIN FECHA", _xludf.LET( _xlpm.dC, C23 - _xlpm.h, _xlpm.fC, IF(_xlpm.dC>=0, _xlpm.dC, 99999), IF(_xlpm.fC=99999, "YA SE VENCIÓ", "EL VENCIMIENTO DE RC se vence en " & _xlpm.fC & " días" ) ) ) ) -> #NAME? | E23: =_xludf.LET( _xlpm.m, C23 - TODAY(), _xlpm.m ) -> #NAME? | F23: =Consolidado!AH114 -> 46179 | G23: =_xludf.LET( _xlpm.h, TODAY(), IF(ISBLANK(F23), "SIN FECHA", _xludf.LET( _xlpm.dC, F23 - _xlpm.h, _xlpm.fC, IF(_xlpm.dC>=0, _xlpm.dC, 99999), IF(_xlpm.fC=99999, "YA SE VENCIÓ", "EL VENCIMIENTO DE RC se vence en " & _xlpm.fC & " días" ) ) ) ) -> #NAME? | H23: =_xludf.LET( _xlpm.m, F23 - TODAY(), _xlpm.m ) -> #NAME?
A24: =Consolidado!A49 -> 43 | B24: =Consolidado!D49 -> Doctorado en Antropología | C24: =Consolidado!AJ49 -> 46623 | D24: =_xludf.LET( _xlpm.h, TODAY(), IF(ISBLANK(C24), "SIN FECHA", _xludf.LET( _xlpm.dC, C24 - _xlpm.h, _xlpm.fC, IF(_xlpm.dC>=0, _xlpm.dC, 99999), IF(_xlpm.fC=99999, "YA SE VENCIÓ", "EL VENCIMIENTO DE RC se vence en " & _xlpm.fC & " días" ) ) ) ) -> #NAME? | E24: =_xludf.LET( _xlpm.m, C24 - TODAY(), _xlpm.m ) -> #NAME? | F24: =Consolidado!AH49 -> 46197 | G24: =_xludf.LET( _xlpm.h, TODAY(), IF(ISBLANK(F24), "SIN FECHA", _xludf.LET( _xlpm.dC, F24 - _xlpm.h, _xlpm.fC, IF(_xlpm.dC>=0, _xlpm.dC, 99999), IF(_xlpm.fC=99999, "YA SE VENCIÓ", "EL VENCIMIENTO DE RC se vence en " & _xlpm.fC & " días" ) ) ) ) -> #NAME? | H24: =_xludf.LET( _xlpm.m, F24 - TODAY(), _xlpm.m ) -> #NAME?
A25: =Consolidado!A100 -> 94 | B25: =Consolidado!D100 -> Ingeniería Civil | C25: =Consolidado!AJ100 -> 46651 | D25: =_xludf.LET( _xlpm.h, TODAY(), IF(ISBLANK(C25), "SIN FECHA", _xludf.LET( _xlpm.dC, C25 - _xlpm.h, _xlpm.fC, IF(_xlpm.dC>=0, _xlpm.dC, 99999), IF(_xlpm.fC=99999, "YA SE VENCIÓ", "EL VENCIMIENTO DE RC se vence en " & _xlpm.fC & " días" ) ) ) ) -> #NAME? | E25: =_xludf.LET( _xlpm.m, C25 - TODAY(), _xlpm.m ) -> #NAME? | F25: =Consolidado!AH100 -> 46224 | G25: =_xludf.LET( _xlpm.h, TODAY(), IF(ISBLANK(F25), "SIN FECHA", _xludf.LET( _xlpm.dC, F25 - _xlpm.h, _xlpm.fC, IF(_xlpm.dC>=0, _xlpm.dC, 99999), IF(_xlpm.fC=99999, "YA SE VENCIÓ", "EL VENCIMIENTO DE RC se vence en " & _xlpm.fC & " días" ) ) ) ) -> #NAME? | H25: =_xludf.LET( _xlpm.m, F25 - TODAY(), _xlpm.m ) -> #NAME?
A26: =Consolidado!A26 -> 20 | B26: =Consolidado!D26 -> Administración de Empresas | C26: =Consolidado!AJ26 -> 46658 | D26: =_xludf.LET( _xlpm.h, TODAY(), IF(ISBLANK(C26), "SIN FECHA", _xludf.LET( _xlpm.dC, C26 - _xlpm.h, _xlpm.fC, IF(_xlpm.dC>=0, _xlpm.dC, 99999), IF(_xlpm.fC=99999, "YA SE VENCIÓ", "EL VENCIMIENTO DE RC se vence en " & _xlpm.fC & " días" ) ) ) ) -> #NAME? | E26: =_xludf.LET( _xlpm.m, C26 - TODAY(), _xlpm.m ) -> #NAME? | F26: =Consolidado!AH26 -> 46231 | G26: =_xludf.LET( _xlpm.h, TODAY(), IF(ISBLANK(F26), "SIN FECHA", _xludf.LET( _xlpm.dC, F26 - _xlpm.h, _xlpm.fC, IF(_xlpm.dC>=0, _xlpm.dC, 99999), IF(_xlpm.fC=99999, "YA SE VENCIÓ", "EL VENCIMIENTO DE RC se vence en " & _xlpm.fC & " días" ) ) ) ) -> #NAME? | H26: =_xludf.LET( _xlpm.m, F26 - TODAY(), _xlpm.m ) -> #NAME?
A27: =Consolidado!A61 -> 55 | B27: =Consolidado!D61 -> Maestría en Educación Popular | C27: =Consolidado!AJ61 -> 46716 | D27: =_xludf.LET( _xlpm.h, TODAY(), IF(ISBLANK(C27), "SIN FECHA", _xludf.LET( _xlpm.dC, C27 - _xlpm.h, _xlpm.fC, IF(_xlpm.dC>=0, _xlpm.dC, 99999), IF(_xlpm.fC=99999, "YA SE VENCIÓ", "EL VENCIMIENTO DE RC se vence en " & _xlpm.fC & " días" ) ) ) ) -> #NAME? | E27: =_xludf.LET( _xlpm.m, C27 - TODAY(), _xlpm.m ) -> #NAME? | F27: =Consolidado!AH61 -> 46290 | G27: =_xludf.LET( _xlpm.h, TODAY(), IF(ISBLANK(F27), "SIN FECHA", _xludf.LET( _xlpm.dC, F27 - _xlpm.h, _xlpm.fC, IF(_xlpm.dC>=0, _xlpm.dC, 99999), IF(_xlpm.fC=99999, "YA SE VENCIÓ", "EL VENCIMIENTO DE RC se vence en " & _xlpm.fC & " días" ) ) ) ) -> #NAME? | H27: =_xludf.LET( _xlpm.m, F27 - TODAY(), _xlpm.m ) -> #NAME?
A28: =Consolidado!A27 -> 21 | B28: =Consolidado!D27 -> Maestría en Gestión de Organizaciones y Proyectos | C28: =Consolidado!AJ27 -> 46802 | D28: =_xludf.LET( _xlpm.h, TODAY(), IF(ISBLANK(C28), "SIN FECHA", _xludf.LET( _xlpm.dC, C28 - _xlpm.h, _xlpm.fC, IF(_xlpm.dC>=0, _xlpm.dC, 99999), IF(_xlpm.fC=99999, "YA SE VENCIÓ", "EL VENCIMIENTO DE RC se vence en " & _xlpm.fC & " días" ) ) ) ) -> #NAME? | E28: =_xludf.LET( _xlpm.m, C28 - TODAY(), _xlpm.m ) -> #NAME? | F28: =Consolidado!AH27 -> 46375 | G28: =_xludf.LET( _xlpm.h, TODAY(), IF(ISBLANK(F28), "SIN FECHA", _xludf.LET( _xlpm.dC, F28 - _xlpm.h, _xlpm.fC, IF(_xlpm.dC>=0, _xlpm.dC, 99999), IF(_xlpm.fC=99999, "YA SE VENCIÓ", "EL VENCIMIENTO DE RC se vence en " & _xlpm.fC & " días" ) ) ) ) -> #NAME? | H28: =_xludf.LET( _xlpm.m, F28 - TODAY(), _xlpm.m ) -> #NAME?
A29: =Consolidado!A62 -> 56 | B29: =Consolidado!D62 -> Maestría en Educación Popular (Santander de Quilichao) | C29: =Consolidado!AJ62 -> 46802 | D29: =_xludf.LET( _xlpm.h, TODAY(), IF(ISBLANK(C29), "SIN FECHA", _xludf.LET( _xlpm.dC, C29 - _xlpm.h, _xlpm.fC, IF(_xlpm.dC>=0, _xlpm.dC, 99999), IF(_xlpm.fC=99999, "YA SE VENCIÓ", "EL VENCIMIENTO DE RC se vence en " & _xlpm.fC & " días" ) ) ) ) -> #NAME? | E29: =_xludf.LET( _xlpm.m, C29 - TODAY(), _xlpm.m ) -> #NAME? | F29: =Consolidado!AH62 -> 46375 | G29: =_xludf.LET( _xlpm.h, TODAY(), IF(ISBLANK(F29), "SIN FECHA", _xludf.LET( _xlpm.dC, F29 - _xlpm.h, _xlpm.fC, IF(_xlpm.dC>=0, _xlpm.dC, 99999), IF(_xlpm.fC=99999, "YA SE VENCIÓ", "EL VENCIMIENTO DE RC se vence en " & _xlpm.fC & " días" ) ) ) ) -> #NAME? | H29: =_xludf.LET( _xlpm.m, F29 - TODAY(), _xlpm.m ) -> #NAME? | I29: Modificación RC, Ok
A30: =Consolidado!A14 -> 8 | B30: =Consolidado!D14 -> Especialización en Sanidad en Producción Agraria Integrada | C30: =Consolidado!AJ14 -> 46815 | D30: =_xludf.LET( _xlpm.h, TODAY(), IF(ISBLANK(C30), "SIN FECHA", _xludf.LET( _xlpm.dC, C30 - _xlpm.h, _xlpm.fC, IF(_xlpm.dC>=0, _xlpm.dC, 99999), IF(_xlpm.fC=99999, "YA SE VENCIÓ", "EL VENCIMIENTO DE RC se vence en " & _xlpm.fC & " días" ) ) ) ) -> #NAME? | E30: =_xludf.LET( _xlpm.m, C30 - TODAY(), _xlpm.m ) -> #NAME? | F30: =Consolidado!AH14 -> 46390 | G30: =_xludf.LET( _xlpm.h, TODAY(), IF(ISBLANK(F30), "SIN FECHA", _xludf.LET( _xlpm.dC, F30 - _xlpm.h, _xlpm.fC, IF(_xlpm.dC>=0, _xlpm.dC, 99999), IF(_xlpm.fC=99999, "YA SE VENCIÓ", "EL VENCIMIENTO DE RC se vence en " & _xlpm.fC & " días" ) ) ) ) -> #NAME? | H30: =_xludf.LET( _xlpm.m, F30 - TODAY(), _xlpm.m ) -> #NAME?
A31: =Consolidado!A116 -> 110 | B31: =Consolidado!D116 -> Ingeniería de Sistemas | C31: =Consolidado!AJ116 -> 46817 | D31: =_xludf.LET( _xlpm.h, TODAY(), IF(ISBLANK(C31), "SIN FECHA", _xludf.LET( _xlpm.dC, C31 - _xlpm.h, _xlpm.fC, IF(_xlpm.dC>=0, _xlpm.dC, 99999), IF(_xlpm.fC=99999, "YA SE VENCIÓ", "EL VENCIMIENTO DE RC se vence en " & _xlpm.fC & " días" ) ) ) ) -> #NAME? | E31: =_xludf.LET( _xlpm.m, C31 - TODAY(), _xlpm.m ) -> #NAME? | F31: =Consolidado!AH116 -> 46392 | G31: =_xludf.LET( _xlpm.h, TODAY(), IF(ISBLANK(F31), "SIN FECHA", _xludf.LET( _xlpm.dC, F31 - _xlpm.h, _xlpm.fC, IF(_xlpm.dC>=0, _xlpm.dC, 99999), IF(_xlpm.fC=99999, "YA SE VENCIÓ", "EL VENCIMIENTO DE RC se vence en " & _xlpm.fC & " días" ) ) ) ) -> #NAME? | H31: =_xludf.LET( _xlpm.m, F31 - TODAY(), _xlpm.m ) -> #NAME?
A32: =Consolidado!A63 -> 57 | B32: =Consolidado!D63 -> Maestría en Educación (MI) | C32: =Consolidado!AJ63 -> 46842 | D32: =_xludf.LET( _xlpm.h, TODAY(), IF(ISBLANK(C32), "SIN FECHA", _xludf.LET( _xlpm.dC, C32 - _xlpm.h, _xlpm.fC, IF(_xlpm.dC>=0, _xlpm.dC, 99999), IF(_xlpm.fC=99999, "YA SE VENCIÓ", "EL VENCIMIENTO DE RC se vence en " & _xlpm.fC & " días" ) ) ) ) -> #NAME? | E32: =_xludf.LET( _xlpm.m, C32 - TODAY(), _xlpm.m ) -> #NAME? | F32: =Consolidado!AH63 -> 46417 | G32: =_xludf.LET( _xlpm.h, TODAY(), IF(ISBLANK(F32), "SIN FECHA", _xludf.LET( _xlpm.dC, F32 - _xlpm.h, _xlpm.fC, IF(_xlpm.dC>=0, _xlpm.dC, 99999), IF(_xlpm.fC=99999, "YA SE VENCIÓ", "EL VENCIMIENTO DE RC se vence en " & _xlpm.fC & " días" ) ) ) ) -> #NAME? | H32: =_xludf.LET( _xlpm.m, F32 - TODAY(), _xlpm.m ) -> #NAME?
